Workbook

Sheet Panel
A1: Panel DCF DINO
A2: Podsumowanie projektu
A3: Kluczowe wyniki
A4: Miara | B4: 2026E | C4: 2030E | D4: CAGR / Δ | F4: Miara | G4: Wartość | H4: Scenariusz
A5: Przychody ze sprzedaży (PLN tys.) | B5: ='Model 3 sprawozdań'!H6 -> 39947286 | C5: ='Model 3 sprawozdań'!L6 -> 68567755 | D5: =POWER(C5/B5,1/4)-1 -> 0.14461165 | F5: Implikowana cena akcji | G5: ='Wycena DCF'!B26 -> 12.830482 | H5: Scenariusz 1
A6: EBITDA (PLN tys.) | B6: ='Model 3 sprawozdań'!H15 -> 2607637.6 | C6: ='Model 3 sprawozdań'!L15 -> 4693836.2 | D6: =POWER(C6/B6,1/4)-1 -> 0.15829764 | F6: Implikowana cena akcji | G6: ='Wycena DCF'!B38 -> 42.773844 | H6: Scenariusz 2
A7: Marża EBIT | B7: ='Model 3 sprawozdań'!H19 -> 0.050276965 | C7: ='Model 3 sprawozdań'!L19 -> 0.049455445 | D7: =C7-B7 -> -0.00082152062 | F7: Bieżąca cena akcji | G7: ='Wycena DCF'!B27 -> 41
A8: WACC | B8: ='Dług i WACC'!H38 -> 0.08451885 | C8: ='Dług i WACC'!L38 -> 0.08451885 | D8: =C8-B8 -> 0 | F8: Premia / (dyskonto) | G8: ='Wycena DCF'!B28 -> -0.68706142 | H8: Scenariusz 1
A9: Dług netto / (gotówka netto) | B9: ='Model 3 sprawozdań'!H89 -> 428014.3 | C9: ='Model 3 sprawozdań'!L89 -> -1372666.4 | D9: =C9-B9 -> -1800680.7 | F9: Premia / (dyskonto) | G9: ='Wycena DCF'!B39 -> 0.04326448 | H9: Scenariusz 2
A11: Założenia prognozy
A12: Miara | B12: 2026E | C12: 2027E | D12: 2028E | E12: 2029E | F12: 2030E
A13: Wzrost przychodów LFL | B13: =Założenia!B26 -> 0.07 | C13: =Założenia!C26 -> 0.058 | D13: =Założenia!D26 -> 0.056 | E13: =Założenia!E26 -> 0.054 | F13: =Założenia!F26 -> 0.052
A14: Inflacja ogólna | B14: =Założenia!B27 -> 0.04 | C14: =Założenia!C27 -> 0.035 | D14: =Założenia!D27 -> 0.03 | E14: =Założenia!E27 -> 0.0275 | F14: =Założenia!F27 -> 0.025
A15: Marża brutto | B15: =Założenia!B28 -> 0.237 | C15: =Założenia!C28 -> 0.238 | D15: =Założenia!D28 -> 0.239 | E15: =Założenia!E28 -> 0.24 | F15: =Założenia!F28 -> 0.24
A16: Nakłady inwestycyjne % sprzedaży | B16: =Założenia!B32 -> 0.061 | C16: =Założenia!C32 -> 0.059 | D16: =Założenia!D32 -> 0.057 | E16: =Założenia!E32 -> 0.055 | F16: =Założenia!F32 -> 0.053
A17: Docelowy udział kapitału własnego | B17: =Założenia!B16 -> 0.95 | C17: =Założenia!B16 -> 0.95 | D17: =Założenia!B16 -> 0.95 | E17: =Założenia!B16 -> 0.95 | F17: =Założenia!B16 -> 0.95
A18: Docelowy udział długu | B18: =Założenia!B17 -> 0.05 | C18: =Założenia!B17 -> 0.05 | D18: =Założenia!B17 -> 0.05 | E18: =Założenia!B17 -> 0.05 | F18: =Założenia!B17 -> 0.05
A19: Skrót historyczny / prognozy
A20: Rok | B20: Przychody ze sprzedaży | C20: EBITDA | D20: Marża EBIT | E20: UFCF | F20: WACC
A21: 2020 | B21: ='Model 3 sprawozdań'!B6 -> 10125815 | C21: ='Model 3 sprawozdań'!B15 -> 837859 | D21: ='Model 3 sprawozdań'!B19 -> 0.063176446 | F21: ='Dług i WACC'!B38 -> 0.032191038
A22: 2021 | B22: ='Model 3 sprawozdań'!C6 -> 13362012 | C22: ='Model 3 sprawozdań'!C15 -> 1023993 | D22: ='Model 3 sprawozdań'!C19 -> 0.058123732 | F22: ='Dług i WACC'!C38 -> 0.036203272
A23: 2022 | B23: ='Model 3 sprawozdań'!D6 -> 19801622 | C23: ='Model 3 sprawozdań'!D15 -> 1537819 | D23: ='Model 3 sprawozdań'!D19 -> 0.062504476 | F23: ='Dług i WACC'!D38 -> 0.079988477
A24: 2023 | B24: ='Model 3 sprawozdań'!E6 -> 25666255 | C24: ='Model 3 sprawozdań'!E15 -> 1875855 | D24: ='Model 3 sprawozdań'!E19 -> 0.059183819 | F24: ='Dług i WACC'!E38 -> 0.082561059
A25: 2024 | B25: ='Model 3 sprawozdań'!F6 -> 29273792 | C25: ='Model 3 sprawozdań'!F15 -> 1908330 | D25: ='Model 3 sprawozdań'!F19 -> 0.05121137 | F25: ='Dług i WACC'!F38 -> 0.080504583
A26: 2025 | B26: ='Model 3 sprawozdań'!G6 -> 33634155 | C26: ='Model 3 sprawozdań'!G15 -> 2041282 | D26: ='Model 3 sprawozdań'!G19 -> 0.045675326 | F26: ='Dług i WACC'!G38 -> 0.080380149
A27: 2026 | B27: ='Model 3 sprawozdań'!H6 -> 39947286 | C27: ='Model 3 sprawozdań'!H15 -> 2607637.6 | D27: ='Model 3 sprawozdań'!H19 -> 0.050276965 | E27: ='Wycena DCF'!B14 -> 136609.49 | F27: ='Dług i WACC'!H38 -> 0.08451885
A28: 2027 | B28: ='Model 3 sprawozdań'!I6 -> 46490651 | C28: ='Model 3 sprawozdań'!I15 -> 3083914.2 | D28: ='Model 3 sprawozdań'!I19 -> 0.050334072 | E28: ='Wycena DCF'!C14 -> 256777.01 | F28: ='Dług i WACC'!I38 -> 0.08451885
A29: 2028 | B29: ='Model 3 sprawozdań'!J6 -> 53512599 | C29: ='Model 3 sprawozdań'!J15 -> 3605803.5 | D29: ='Model 3 sprawozdań'!J19 -> 0.050382328 | E29: ='Wycena DCF'!D14 -> 432514.65 | F29: ='Dług i WACC'!J38 -> 0.08451885
A30: 2029 | B30: ='Model 3 sprawozdań'!K6 -> 60914462 | C30: ='Model 3 sprawozdań'!K15 -> 4167907.9 | D30: ='Model 3 sprawozdań'!K19 -> 0.050422305 | E30: ='Wycena DCF'!E14 -> 647858.54 | F30: ='Dług i WACC'!K38 -> 0.08451885
A31: 2030 | B31: ='Model 3 sprawozdań'!L6 -> 68567755 | C31: ='Model 3 sprawozdań'!L15 -> 4693836.2 | D31: ='Model 3 sprawozdań'!L19 -> 0.049455445 | E31: ='Wycena DCF'!F14 -> 846822.43 | F31: ='Dług i WACC'!L38 -> 0.08451885

Sheet Założenia
A1: Założenia
A2: Statyczne założenia wyceny / modelu
A3: Miara | B3: Wartość | H3: Uwagi
A4: Mnożnik EV/EBITDA | B4: 15
A5: Stopa wolna od ryzyka | B5: 0.0588 | H5: Polski 10-letni instrument odniesienia 2026; założenie WACC na przyszłość, stopa z 23 maja 2026 r.
A6: Beta | B6: 0.51 | H6: Założenie beta kapitału własnego
A7: Premia za ryzyko kapitału własnego | B7: 0.0533 | H7: Założenie rynkowej premii za ryzyko
A8: Stopa wzrostu rezydualnego | B8: 0.03
A9: Bieżąca cena akcji (PLN) | B9: ='Dane źródłowe'!G100 -> 41 | H9: Cena z 02.01.2026
A10: Liczba akcji (tys.) | B10: ='Dane źródłowe'!G97 -> 980400 | H10: Powiązane z liczbą akcji w 2025 r.; 2020-2024 stanowiły 1/10 2025 r.
A11: Liczba dni w roku | B11: 365 | H11: Używane do dni kapitału obrotowego
A12: Dzielnik jednostek | B12: 1000 | H12: Używane do konwersji jednostek
A13: Minimalny poziom gotówki % sprzedaży | B13: 0.02
A14: Stopa przychodów odsetkowych od średniej gotówki | B14: 0.02
A15: Ustawowa stawka podatkowa | B15: 0.19
A16: Docelowy udział kapitału własnego | B16: 0.95
A17: Docelowy udział długu | B17: =1-B16 -> 0.05
A18: Historyczne założenia rynkowe
A19: Miara | B19: 2020A | C19: 2021A | D19: 2022A | E19: 2023A | F19: 2024A | G19: 2025A | H19: Źródło / uwagi
A20: Cena rynkowa DINO / akcję (PLN) | B20: ='Dane źródłowe'!B100 -> 200 | C20: ='Dane źródłowe'!C100 -> 300 | D20: ='Dane źródłowe'!D100 -> 330 | E20: ='Dane źródłowe'!E100 -> 420 | F20: ='Dane źródłowe'!F100 -> 400 | G20: ='Dane źródłowe'!G100 -> 41
A21: Stopa wolna od ryzyka | B21: ='Dane źródłowe'!B101 -> 0.015 | C21: ='Dane źródłowe'!C101 -> 0.0194 | D21: ='Dane źródłowe'!D101 -> 0.0605 | E21: ='Dane źródłowe'!E101 -> 0.0581 | F21: ='Dane źródłowe'!F101 -> 0.0553 | G21: ='Dane źródłowe'!G101 -> 0.055
A22: Liczba akcji (tys.) | B22: ='Dane źródłowe'!B97 -> 98040 | C22: ='Dane źródłowe'!C97 -> 98040 | D22: ='Dane źródłowe'!D97 -> 98040 | E22: ='Dane źródłowe'!E97 -> 98040 | F22: ='Dane źródłowe'!F97 -> 98040 | G22: ='Dane źródłowe'!G97 -> 980400 | H22: 2020-2024 = 1/10 2025 r.
A23: Kapitalizacja rynkowa (PLN tys.) | B23: =B20*B22 -> 19608000 | C23: =C20*C22 -> 29412000 | D23: =D20*D22 -> 32353200 | E23: =E20*E22 -> 41176800 | F23: =F20*F22 -> 39216000 | G23: =G20*G22 -> 40196400
A24: Założenia prognozy operacyjnej
A25: Miara | B25: 2026E | C25: 2027E | D25: 2028E | E25: 2029E | F25: 2030E | H25: Źródło / uwagi
A26: Wzrost przychodów LFL | B26: 0.07 | C26: 0.058 | D26: 0.056 | E26: 0.054 | F26: 0.052 | H26: Główny czynnik wzrostu przychodów
A27: Inflacja ogólna | B27: 0.04 | C27: 0.035 | D27: 0.03 | E27: 0.0275 | F27: 0.025
A28: Marża brutto | B28: 0.237 | C28: 0.238 | D28: 0.239 | E28: 0.24 | F28: 0.24
A29: Wzrost liczby sklepów | B29: 0.11 | C29: 0.1 | D29: 0.09 | E29: 0.08 | F29: 0.07 | H29: Łącznie daje 5000 sklepów w 2030 r.
A30: Pozostałe przychody operacyjne % sprzedaży | B30: 0.0008 | C30: 0.0008 | D30: 0.0008 | E30: 0.0008 | F30: 0.0008 | H30: Wskaźnik pomocniczy
A31: Amortyzacja % sprzedaży | B31: 0.015 | C31: 0.016 | D31: 0.017 | E31: 0.018 | F31: 0.019 | H31: Założenie prognozy amortyzacji
A32: Nakłady inwestycyjne % sprzedaży | B32: 0.061 | C32: 0.059 | D32: 0.057 | E32: 0.055 | F32: 0.053
A33: Dni zapasów | B33: 50 | C33: 50 | D33: 49.5 | E33: 49 | F33: 48.5
A34: Dni należności | B34: 4 | C34: 4 | D34: 4 | E34: 4 | F34: 4
A35: Dni zobowiązań | B35: 74 | C35: 74 | D35: 73.5 | E35: 73 | F35: 72.5
A36: Założenia alokacji aktywów trwałych
A37: Miara | B37: 2026E | C37: 2027E | D37: 2028E | E37: 2029E | F37: 2030E
A38: Alokacja nakładów inwestycyjnych na PPE / ROU | B38: 0.95 | C38: 0.95 | D38: 0.95 | E38: 0.95 | F38: 0.95
A39: Alokacja nakładów inwestycyjnych na wartości niematerialne | B39: 0.05 | C39: 0.05 | D39: 0.05 | E39: 0.05 | F39: 0.05
A40: Alokacja amortyzacji PPE / ROU | B40: 0.95 | C40: 0.95 | D40: 0.95 | E40: 0.95 | F40: 0.95
...

Sheet Dane źródłowe
A1: Dane źródłowe
A3: Historyczny rachunek zysków i strat
A4: Pozycja | B4: 2020 | C4: 2021 | D4: 2022 | E4: 2023 | F4: 2024 | G4: 2025
A5: Przychody ze sprzedaży | B5: 10125815 | C5: 13362012 | D5: 19801622 | E5: 25666255 | F5: 29273792 | G5: 33634155
A6: Koszt własny sprzedaży | B6: -7521986 | C6: -10038342 | D6: -15038630 | E6: -19741459 | F6: -22463233 | G6: -25723078
A7: Zysk brutto ze sprzedaży | B7: 2603829 | C7: 3323670 | D7: 4762992 | E7: 5924796 | F7: 6810559 | G7: 7911077
A8: Pozostałe przychody operacyjne | B8: 7598 | C8: 14364 | D8: 16282 | E8: 13477 | F8: 24185 | G8: 29231
A9: Koszty sprzedaży i marketingu | B9: -1668084 | C9: -2181963 | D9: -3080061 | E9: -3878421 | F9: -4678717 | G9: -5576262
A10: Koszty ogólnego zarządu | B10: -99783 | C10: -117285 | D10: -143217 | E10: -173736 | F10: -233653 | G10: -302944
A11: Pozostałe koszty operacyjne | B11: -5701 | C11: -14793 | D11: -18177 | E11: -10261 | F11: -14044 | G11: -19820
A12: Zysk operacyjny | B12: 837859 | C12: 1023993 | D12: 1537819 | E12: 1875855 | F12: 1908330 | G12: 2041282
A13: Przychody finansowe | B13: 3237 | C13: 1119 | D13: 5092 | E13: 10442 | F13: 6657 | G13: 8316
A14: Koszty finansowe | B14: -52096 | C14: -46703 | D14: -141293 | E14: -147316 | F14: -121424 | G14: -122945
A15: Zysk przed opodatkowaniem | B15: 789000 | C15: 978409 | D15: 1401618 | E15: 1738981 | F15: 1793563 | G15: 1926653
... A19: Zysk przypadający udziałowcom niekontrolującym | B19: 0 | C19: 0 | D19: 0 | E19: 0 | F19: 749 | G19: 437
A20: Historyczny bilans
A21: Pozycja | B21: 2020 | C21: 2021 | D21: 2022 | E21: 2023 | F21: 2024 | G21: 2025
A22: Rzeczowe aktywa trwałe | B22: 3749480 | C22: 4911353 | D22: 6070032 | E22: 6874672 | F22: 8230915 | G22: 9774681
A23: Aktywa z tytułu prawa do użytkowania | B23: 184538 | C23: 139931 | D23: 105116 | E23: 93499 | F23: 141350 | G23: 217006
A24: Wartości niematerialne | B24: 99050 | C24: 96947 | D24: 94737 | E24: 115056 | F24: 169964 | G24: 176185
A25: Pozostałe aktywa niefinansowe (długoterminowe) | B25: 6 | C25: 0 | D25: 0 | E25: 0 | F25: 0 | G25: 0
A26: Aktywa z tytułu odroczonego podatku | B26: 20738 | C26: 35116 | D26: 26468 | E26: 41323 | F26: 74149 | G26: 31376
A27: Aktywa trwałe razem | B27: 4053812 | C27: 5183347 | D27: 6296353 | E27: 7124550 | F27: 8616378 | G27: 10199248
A28: Zapasy | B28: 875147 | C28: 1373463 | D28: 1978778 | E28: 2638859 | F28: 3081444 | G28: 3548100
A29: Należności handlowe i pozostałe | B29: 86822 | C29: 144012 | D29: 274872 | E29: 330389 | F29: 376480 | G29: 372038
A30: Należności z tytułu podatku dochodowego | B30: 2 | C30: 55 | D30: 0 | E30: 103 | F30: 220 | G30: 18596
A31: Pozostałe aktywa niefinansowe (bieżące) | B31: 73367 | C31: 47712 | D31: 69096 | E31: 64049 | F31: 88186 | G31: 76477
A32: Pozostałe aktywa finansowe | B32: 942 | C32: 1327 | D32: 1242 | E32: 1376 | F32: 2064 | G32: 2007
... A61: KAPITAŁ WŁASNY I ZOBOWIĄZANIA RAZEM | B61: 5570510 | C61: 7168531 | D61: 9003059 | E61: 10377715 | F61: 13055794 | G61: 15171280
A62: Historyczny rachunek przepływów pieniężnych
A63: Pozycja | B63: 2020 | C63: 2021 | D63: 2022 | E63: 2023 | F63: 2024 | G63: 2025
A64: Amortyzacja | B64: 198146 | C64: 247343 | D64: 300129 | E64: 356828 | F64: 409179 | G64: 505031 | H64: =SUM(B64+B65-B66+B67-B68-B69+B70-B71) -> 1654226
A65: Zysk przed opodatkowaniem | B65: =B15 -> 789000 | C65: =C15 -> 978409 | D65: =D15 -> 1401618 | E65: =E15 -> 1738981 | F65: =F15 -> 1793563 | G65: =G15 -> 1926653
A66: Zapłacony podatek dochodowy | B66: -138680 | C66: -173004 | D66: -234653 | E66: -291839 | F66: -417176 | G66: -362312
A67: Koszty odsetkowe | B67: 52012 | C67: 46645 | D67: 141293 | E67: 147316 | F67: 121353 | G67: 122837
A68: Zmiana należności | B68: -43201 | C68: -24880 | D68: -152796 | E68: -54245 | F68: -55966 | G68: 14973
A69: Zmiana zapasów | B69: -251152 | C69: -498316 | D69: -605315 | E69: -660081 | F69: -424123 | G69: -466656
A70: Zmiana zobowiązań z wyłączeniem kredytów i pożyczek | B70: 197916 | C70: 728449 | D70: 366502 | E70: 537055 | F70: 1126352 | G70: 948166
A71: Pozostałe | B71: =B72-SUM(B64:B70) -> 15881 | C71: =C72-SUM(C64:C70) -> 21685 | D71: =D72-SUM(D64:D70) -> 36644 | E71: =E72-SUM(E64:E70) -> -2475 | F71: =F72-SUM(F64:F70) -> 4271 | G71: =G72-SUM(G64:G70) -> 8753
A72: Środki pieniężne netto z działalności operacyjnej | B72: 819922 | C72: 1326331 | D72: 1253422 | E72: 1771540 | F72: 2557453 | G72: 2697445
...

Sheet Czynniki operacyjne
A1: Czynniki operacyjne / budowa przychodów
A2: Mostek operacyjny oparty na formułach. Prognozowane przychody są napędzane wzrostem LFL; metryki sklepów są operacyjnymi KPI.
A3: Miara | B3: 2020 | C3: 2021 | D3: 2022 | E3: 2023 | F3: 2024 | G3: 2025 | H3: 2026 | I3: 2027 | J3: 2028 | K3: 2029 | L3: 2030
A4: Okres | B4: 2020A | C4: 2021A | D4: 2022A | E4: 2023A | F4: 2024A | G4: 2025A | H4: 2026E | I4: 2027E | J4: 2028E | K4: 2029E | L4: 2030E
A5: Mostek liczby sklepów i budowa przychodów
A6: Liczba sklepów (#) | B6: ='Dane źródłowe'!B92 -> 1473 | C6: ='Dane źródłowe'!C92 -> 1815 | D6: ='Dane źródłowe'!D92 -> 2156 | E6: ='Dane źródłowe'!E92 -> 2406 | F6: ='Dane źródłowe'!F92 -> 2688 | G6: ='Dane źródłowe'!G92 -> 3033 | H6: =G6*(1+Założenia!B29) -> 3366.63 | I6: =H6*(1+Założenia!C29) -> 3703.293 | J6: =I6*(1+Założenia!D29) -> 4036.5894 | K6: =J6*(1+Założenia!E29) -> 4359.5165 | L6: =K6*(1+Założenia!F29) -> 4664.6827
A7: Wzrost liczby sklepów | C7: =C6/B6-1 -> 0.23217923 | D7: =D6/C6-1 -> 0.18787879 | E7: =E6/D6-1 -> 0.11595547 | F7: =F6/E6-1 -> 0.11720698 | G7: =G6/F6-1 -> 0.12834821 | H7: =Założenia!B29 -> 0.11 | I7: =Założenia!C29 -> 0.1 | J7: =Założenia!D29 -> 0.09 | K7: =Założenia!E29 -> 0.08 | L7: =Założenia!F29 -> 0.07
A8: Powierzchnia sprzedaży (tys. m²) | B8: ='Dane źródłowe'!B93 -> 573 | C8: ='Dane źródłowe'!C93 -> 710 | D8: ='Dane źródłowe'!D93 -> 848 | E8: ='Dane źródłowe'!E93 -> 948 | F8: ='Dane źródłowe'!F93 -> 1061 | G8: ='Dane źródłowe'!G93 -> 1200 | H8: =H6*H10/1000 -> 1335.3666 | I8: =I6*I10/1000 -> 1472.6066 | J8: =J6*J10/1000 -> 1609.1778 | K8: =K6*K10/1000 -> 1742.2715 | L8: =L6*L10/1000 -> 1868.8952
A9: Wzrost powierzchni sprzedaży | C9: =C8/B8-1 -> 0.2390925 | D9: =D8/C8-1 -> 0.1943662 | E9: =E8/D8-1 -> 0.11792453 | F9: =F8/E8-1 -> 0.11919831 | G9: =G8/F8-1 -> 0.13100848 | H9: =H8/G8-1 -> 0.11280553 | I9: =I8/H8-1 -> 0.10277324 | J9: =J8/I8-1 -> 0.092741119 | ... L9: =L8/K8-1 -> 0.072677357
A10: Średnia powierzchnia sprzedaży / sklep (m²) | B10: ='Dane źródłowe'!B94 -> 389.00204 | C10: ='Dane źródłowe'!C94 -> 391.18457 | D10: ='Dane źródłowe'!D94 -> 393.32096 | E10: ='Dane źródłowe'!E94 -> 394.01496 | F10: ='Dane źródłowe'!F94 -> 394.71726 | G10: ='Dane źródłowe'!G94 -> 395.64787 | H10: =G10+1 -> 396.64787 | I10: =H10+1 -> 397.64787 | J10: =I10+1 -> 398.64787 | K10: =J10+1 -> 399.64787 | L10: =K10+1 -> 400.64787
A11: Przychody / sklep (PLN tys.) | B11: =B13/B6 -> 6874.2804 | C11: =C13/C6 -> 7361.9901 | D11: =D13/D6 -> 9184.4258 | E11: =E13/E6 -> 10667.604 | F11: =F13/F6 -> 10890.548 | G11: =G13/G6 -> 11089.402 | H11: =G11*(1+Założenia!B26) -> 11865.66 | I11: =H11*(1+Założenia!C26) -> 12553.868 | J11: =I11*(1+Założenia!D26) -> 13256.885 | K11: =J11*(1+Założenia!E26) -> 13972.756 | L11: =K11*(1+Założenia!F26) -> 14699.34
A12: Wzrost przychodów / sklep | C12: =C11/B11-1 -> 0.070947019 | D12: =D11/C11-1 -> 0.24754661 | E12: =E11/D11-1 -> 0.16148839 | F12: =F11/E11-1 -> 0.020899137 | G12: =G11/F11-1 -> 0.018259317 | H12: =H11/G11-1 -> 0.07 | I12: =I11/H11-1 -> 0.058 | J12: =J11/I11-1 -> 0.056 | ... L12: =L11/K11-1 -> 0.052
A13: Przychody ze sprzedaży (PLN tys.) | B13: ='Dane źródłowe'!B5 -> 10125815 | C13: ='Dane źródłowe'!C5 -> 13362012 | D13: ='Dane źródłowe'!D5 -> 19801622 | E13: ='Dane źródłowe'!E5 -> 25666255 | F13: ='Dane źródłowe'!F5 -> 29273792 | G13: ='Dane źródłowe'!G5 -> 33634155 | H13: =H6*H11 -> 39947286 | I13: =I6*I11 -> 46490651 | J13: =J6*J11 -> 53512599 | K13: =K6*K11 -> 60914462 | L13: =L6*L11 -> 68567755
A14: Wzrost przychodów | C14: =C13/B13-1 -> 0.31959867 | D14: =D13/C13-1 -> 0.48193416 | E14: =E13/D13-1 -> 0.29616932 | F14: =F13/E13-1 -> 0.14055564 | G14: =G13/F13-1 -> 0.14895108 | H14: =H13/G13-1 -> 0.1877 | I14: =I13/H13-1 -> 0.1638 | J14: =J13/I13-1 -> 0.15104 | ... L14: =L13/K13-1 -> 0.12564
A15: Marża brutto | B15: ='Dane źródłowe'!B7/B13 -> 0.2571476 | C15: ='Dane źródłowe'!C7/C13 -> 0.24874023 | D15: ='Dane źródłowe'!D7/D13 -> 0.24053545 | E15: ='Dane źródłowe'!E7/E13 -> 0.23083991 | F15: ='Dane źródłowe'!F7/F13 -> 0.23265039 | G15: ='Dane źródłowe'!G7/G13 -> 0.23520963 | H15: =Założenia!B28 -> 0.237 | I15: =Założenia!C28 -> 0.238 | J15: =Założenia!D28 -> 0.239 | K15: =Założenia!E28 -> 0.24 | L15: =Założenia!F28 -> 0.24
A16: Marża EBITDA | B16: ='Model 3 sprawozdań'!B15/'Model 3 sprawozdań'!B6 -> 0.082744846 | C16: ='Model 3 sprawozdań'!C15/'Model 3 sprawozdań'!C6 -> 0.076634642 | D16: ='Model 3 sprawozdań'!D15/'Model 3 sprawozdań'!D6 -> 0.077661264 | E16: ='Model 3 sprawozdań'!E15/'Model 3 sprawozdań'!E6 -> 0.073086432 | F16: ='Model 3 sprawozdań'!F15/'Model 3 sprawozdań'!F6 -> 0.065189026 | G16: ='Model 3 sprawozdań'!G15/'Model 3 sprawozdań'!G6 -> 0.060690747 | H16: ='Model 3 sprawozdań'!H15/'Model 3 sprawozdań'!H6 -> 0.065276965 | I16: ='Model 3 sprawozdań'!I15/'Model 3 sprawozdań'!I6 -> 0.066334072 | ... L16: ='Model 3 sprawozdań'!L15/'Model 3 sprawozdań'!L6 -> 0.068455445
A17: Marża EBIT | B17: ='Model 3 sprawozdań'!B18/'Model 3 sprawozdań'!B6 -> 0.063176446 | C17: ='Model 3 sprawozdań'!C18/'Model 3 sprawozdań'!C6 -> 0.058123732 | D17: ='Model 3 sprawozdań'!D18/'Model 3 sprawozdań'!D6 -> 0.062504476 | E17: ='Model 3 sprawozdań'!E18/'Model 3 sprawozdań'!E6 -> 0.059183819 | F17: ='Model 3 sprawozdań'!F18/'Model 3 sprawozdań'!F6 -> 0.05121137 | G17: ='Model 3 sprawozdań'!G18/'Model 3 sprawozdań'!G6 -> 0.045675326 | H17: ='Model 3 sprawozdań'!H18/'Model 3 sprawozdań'!H6 -> 0.050276965 | I17: ='Model 3 sprawozdań'!I18/'Model 3 sprawozdań'!I6 -> 0.050334072 | ... L17: ='Model 3 sprawozdań'!L18/'Model 3 sprawozdań'!L6 -> 0.049455445
A18: Nakłady inwestycyjne % sprzedaży | B18: =-'Model 3 sprawozdań'!B35/'Model 3 sprawozdań'!B6 -> 0.098957467 | C18: =-'Model 3 sprawozdań'!C35/'Model 3 sprawozdań'!C6 -> 0.099955306 | D18: =-'Model 3 sprawozdań'!D35/'Model 3 sprawozdań'!D6 -> 0.073019523 | E18: =-'Model 3 sprawozdań'!E35/'Model 3 sprawozdań'!E6 -> 0.045696694 | F18: =-'Model 3 sprawozdań'!F35/'Model 3 sprawozdań'!F6 -> 0.05335537 | G18: =-'Model 3 sprawozdań'!G35/'Model 3 sprawozdań'!G6 -> 0.062051299 | H18: =-'Model 3 sprawozdań'!H35/'Model 3 sprawozdań'!H6 -> 0.061 | I18: =-'Model 3 sprawozdań'!I35/'Model 3 sprawozdań'!I6 -> 0.059 | ... L18: =-'Model 3 sprawozdań'!L35/'Model 3 sprawozdań'!L6 -> 0.053
A19: Operacyjny kapitał obrotowy netto % sprzedaży | B19: ='Model 3 sprawozdań'!B90/'Model 3 sprawozdań'!B6 -> -0.077554844 | C19: ='Model 3 sprawozdań'!C90/'Model 3 sprawozdań'!C6 -> -0.078189048 | D19: ='Model 3 sprawozdań'!D90/'Model 3 sprawozdań'!D6 -> -0.034259012 | E19: ='Model 3 sprawozdań'!E90/'Model 3 sprawozdań'!E6 -> -0.021349277 | F19: ='Model 3 sprawozdań'!F90/'Model 3 sprawozdań'!F6 -> -0.042793909 | G19: ='Model 3 sprawozdań'!G90/'Model 3 sprawozdań'!G6 -> -0.050406023 | H19: ='Model 3 sprawozdań'!H90/'Model 3 sprawozdań'!H6 -> -0.051135432 | I19: ='Model 3 sprawozdań'!I90/'Model 3 sprawozdań'!I6 -> -0.051690931 | ... L19: ='Model 3 sprawozdań'!L90/'Model 3 sprawozdań'!L6 -> -0.053050139

Sheet Model 3 sprawozdań
A1: Zintegrowany model trzech sprawozdań
A2: Wszystkie komórki niebędące danymi wejściowymi są oparte na formułach z arkuszy Dane źródłowe i Założenia. Wartości wprowadzone na sztywno są odizolowane wyłącznie w arkuszach Dane źródłowe i Założenia.
A3: Miara | B3: 2020 | C3: 2021 | D3: 2022 | E3: 2023 | F3: 2024 | G3: 2025 | H3: 2026 | I3: 2027 | J3: 2028 | K3: 2029 | L3: 2030
A4: Okres | B4: 2020A | C4: 2021A | D4: 2022A | E4: 2023A | F4: 2024A | G4: 2025A | H4: 2026E | I4: 2027E | J4: 2028E | K4: 2029E | L4: 2030E
A5: Rachunek zysków i strat
A6: Przychody ze sprzedaży | B6: ='Dane źródłowe'!B5 -> 10125815 | C6: ='Dane źródłowe'!C5 -> 13362012 | D6: ='Dane źródłowe'!D5 -> 19801622 | E6: ='Dane źródłowe'!E5 -> 25666255 | F6: ='Dane źródłowe'!F5 -> 29273792 | G6: ='Dane źródłowe'!G5 -> 33634155 | H6: ='Czynniki operacyjne'!H13 -> 39947286 | I6: ='Czynniki operacyjne'!I13 -> 46490651 | J6: ='Czynniki operacyjne'!J13 -> 53512599 | K6: ='Czynniki operacyjne'!K13 -> 60914462 | L6: ='Czynniki operacyjne'!L13 -> 68567755
A7: Wzrost przychodów | C7: =C6/B6-1 -> 0.31959867 | D7: =D6/C6-1 -> 0.48193416 | E7: =E6/D6-1 -> 0.29616932 | F7: =F6/E6-1 -> 0.14055564 | G7: =G6/F6-1 -> 0.14895108 | H7: =H6/G6-1 -> 0.1877 | I7: =I6/H6-1 -> 0.1638 | J7: =J6/I6-1 -> 0.15104 | ... L7: =L6/K6-1 -> 0.12564
A8: Koszt własny sprzedaży | B8: ='Dane źródłowe'!B6 -> -7521986 | C8: ='Dane źródłowe'!C6 -> -10038342 | D8: ='Dane źródłowe'!D6 -> -15038630 | E8: ='Dane źródłowe'!E6 -> -19741459 | F8: ='Dane źródłowe'!F6 -> -22463233 | G8: ='Dane źródłowe'!G6 -> -25723078 | H8: =-H6*(1-Założenia!B28) -> -30479779 | I8: =-I6*(1-Założenia!C28) -> -35425876 | J8: =-J6*(1-Założenia!D28) -> -40723088 | K8: =-K6*(1-Założenia!E28) -> -46294991 | L8: =-L6*(1-Założenia!F28) -> -52111494
A9: Zysk brutto | B9: =B6+B8 -> 2603829 | C9: =C6+C8 -> 3323670 | D9: =D6+D8 -> 4762992 | E9: =E6+E8 -> 5924796 | F9: =F6+F8 -> 6810559 | G9: =G6+G8 -> 7911077 | H9: =H6+H8 -> 9467506.8 | I9: =I6+I8 -> 11064775 | ... L9: =L6+L8 -> 16456261
A10: Marża brutto | B10: =B9/B6 -> 0.2571476 | C10: =C9/C6 -> 0.24874023 | D10: =D9/D6 -> 0.24053545 | E10: =E9/E6 -> 0.23083991 | F10: =F9/F6 -> 0.23265039 | G10: =G9/G6 -> 0.23520963 | H10: =H9/H6 -> 0.237 | I10: =I9/I6 -> 0.238 | ... L10: =L9/L6 -> 0.24
A11: Pozostałe przychody operacyjne | B11: ='Dane źródłowe'!B8 -> 7598 | C11: ='Dane źródłowe'!C8 -> 14364 | D11: ='Dane źródłowe'!D8 -> 16282 | E11: ='Dane źródłowe'!E8 -> 13477 | F11: ='Dane źródłowe'!F8 -> 24185 | G11: ='Dane źródłowe'!G8 -> 29231 | H11: =H6*Założenia!B30 -> 31957.829 | I11: =I6*Założenia!C30 -> 37192.521 | J11: =J6*Założenia!D30 -> 42810.079 | K11: =K6*Założenia!E30 -> 48731.57 | L11: =L6*Założenia!F30 -> 54854.204
A12: Koszty sprzedaży i marketingu | B12: ='Dane źródłowe'!B9 -> -1668084 | C12: ='Dane źródłowe'!C9 -> -2181963 | D12: ='Dane źródłowe'!D9 -> -3080061 | E12: ='Dane źródłowe'!E9 -> -3878421 | F12: ='Dane źródłowe'!F9 -> -4678717 | G12: ='Dane źródłowe'!G9 -> -5576262 | H12: =-H6*(16.5%-0.2%) -> -6511407.6 | I12: =-I6*(16.5%-0.2%) -> -7577976.2 | J12: =-J6*(16.5%-0.2%) -> -8722553.7 | K12: =-K6*(16.5%-0.2%) -> -9929057.3 | L12: =-L6*(16.5%-0.2%) -> -11176544
A13: Koszty ogólnego zarządu | B13: ='Dane źródłowe'!B10 -> -99783 | C13: ='Dane źródłowe'!C10 -> -117285 | D13: ='Dane źródłowe'!D10 -> -143217 | E13: ='Dane źródłowe'!E10 -> -173736 | F13: ='Dane źródłowe'!F10 -> -233653 | G13: ='Dane źródłowe'!G10 -> -302944 | H13: =G13*(1.005+H7-0.5%) -> -359806.59 | I13: =H13*(1.005+I7-0.5%) -> -418742.91 | J13: =I13*(1.005+J7-0.5%) -> -481989.84 | K13: =J13*(1.005+K7-0.5%) -> -548658.67 | L13: =K13*(1.005+L7-0.5%) -> -617592.15
A14: Pozostałe koszty operacyjne | B14: ='Dane źródłowe'!B11 -> -5701 | C14: ='Dane źródłowe'!C11 -> -14793 | D14: ='Dane źródłowe'!D11 -> -18177 | E14: ='Dane źródłowe'!E11 -> -10261 | F14: ='Dane źródłowe'!F11 -> -14044 | G14: ='Dane źródłowe'!G11 -> -19820 | H14: =G14*(1+Założenia!B27) -> -20612.8 | I14: =H14*(1+Założenia!C27) -> -21334.248 | J14: =I14*(1+Założenia!D27) -> -21974.275 | K14: =J14*(1+Założenia!E27) -> -22578.568 | L14: =K14*(1+Założenia!F27) -> -23143.032
A15: EBITDA | B15: =SUM(B6,B8,B11,B12,B13,B14) -> 837859 | C15: =SUM(C6,C8,C11,C12,C13,C14) -> 1023993 | D15: =SUM(D6,D8,D11,D12,D13,D14) -> 1537819 | E15: =SUM(E6,E8,E11,E12,E13,E14) -> 1875855 | F15: =SUM(F6,F8,F11,F12,F13,F14) -> 1908330 | G15: =SUM(G6,G8,G11,G12,G13,G14) -> 2041282 | H15: =SUM(H6,H8,H11,H12,H13,H14) -> 2607637.6 | I15: =SUM(I6,I8,I11,I12,I13,I14) -> 3083914.2 | ... L15: =SUM(L6,L8,L11,L12,L13,L14) -> 4693836.2
A16: Marża EBITDA | B16: =B15/B6 -> 0.082744846 | C16: =C15/C6 -> 0.076634642 | D16: =D15/D6 -> 0.077661264 | E16: =E15/E6 -> 0.073086432 | F16: =F15/F6 -> 0.065189026 | G16: =G15/G6 -> 0.060690747 | H16: =H15/H6 -> 0.065276965 | I16: =I15/I6 -> 0.066334072 | ... L16: =L15/L6 -> 0.068455445
A17: Koszt amortyzacji | B17: =-'Dane źródłowe'!B64 -> -198146 | C17: =-'Dane źródłowe'!C64 -> -247343 | D17: =-'Dane źródłowe'!D64 -> -300129 | E17: =-'Dane źródłowe'!E64 -> -356828 | F17: =-'Dane źródłowe'!F64 -> -409179 | G17: =-'Dane źródłowe'!G64 -> -505031 | H17: =-H6*Założenia!B31 -> -599209.29 | I17: =-I6*Założenia!C31 -> -743850.42 | J17: =-J6*Założenia!D31 -> -909714.19 | K17: =-K6*Założenia!E31 -> -1096460.3 | L17: =-L6*Założenia!F31 -> -1302787.3
A18: EBIT | B18: =B15+B17 -> 639713 | C18: =C15+C17 -> 776650 | D18: =D15+D17 -> 1237690 | E18: =E15+E17 -> 1519027 | F18: =F15+F17 -> 1499151 | G18: =G15+G17 -> 1536251 | H18: =H15+H17 -> 2008428.3 | I18: =I15+I17 -> 2340063.8 | ... L18: =L15+L17 -> 3391048.8
A19: Marża EBIT | B19: =B18/B6 -> 0.063176446 | C19: =C18/C6 -> 0.058123732 | D19: =D18/D6 -> 0.062504476 | E19: =E18/E6 -> 0.059183819 | F19: =F18/F6 -> 0.05121137 | G19: =G18/G6 -> 0.045675326 | H19: =H18/H6 -> 0.050276965 | I19: =I18/I6 -> 0.050334072 | ... L19: =L18/L6 -> 0.049455445
A20: Przychody finansowe | B20: ='Dane źródłowe'!B13 -> 3237 | C20: ='Dane źródłowe'!C13 -> 1119 | D20: ='Dane źródłowe'!D13 -> 5092 | E20: ='Dane źródłowe'!E13 -> 10442 | F20: ='Dane źródłowe'!F13 -> 6657 | G20: ='Dane źródłowe'!G13 -> 8316 | H20: =G44*Założenia!B14 -> 19096.28 | I20: =H44*Założenia!B14 -> 3546.4866 | J20: =I44*Założenia!B14 -> 7400.712 | K20: =J44*Założenia!B14 -> 14683.683 | L20: =K44*Założenia!B14 -> 26224.734
A21: Koszty odsetkowe - dług / leasingi / obligacje | B21: -30379 | C21: -26155 | D21: -124832 | E21: -127285 | F21: -90957 | G21: -67946 | H21: =-'Dług i WACC'!H20 -> -47623.472 | I21: =-'Dług i WACC'!I20 -> -43178.959 | J21: =-'Dług i WACC'!J20 -> -44893.443 | K21: =-'Dług i WACC'!K20 -> -46812.638 | L21: =-'Dług i WACC'!L20 -> -48927.768
A22: Koszty odsetkowe - zobowiązania handlowe | B22: -18139 | C22: -20434 | D22: -15839 | E22: -19600 | F22: -29836 | G22: -54614 | H22: =-'Dług i WACC'!H18 -> -57139.929 | I22: =-'Dług i WACC'!I18 -> -67865.094 | J22: =-'Dług i WACC'!J18 -> -78981.396 | K22: =-'Dług i WACC'!K18 -> -90910.746 | L22: =-'Dług i WACC'!L18 -> -103485.52
A23: Koszty odsetkowe - pozostałe zobowiązania | B23: -3494 | C23: -56 | D23: -622 | E23: -431 | F23: -560 | G23: -277 | H23: =-'Dług i WACC'!H19 -> 0 | I23: =-'Dług i WACC'!I19 -> 0 | J23: =-'Dług i WACC'!J19 -> 0 | K23: =-'Dług i WACC'!K19 -> 0 | L23: =-'Dług i WACC'!L19 -> 0
A24: Pozostałe koszty / (przychody) finansowe | B24: -84 | C24: -58 | D24: 0 | E24: 0 | F24: -71 | G24: -108 | H24: =-Założenia!B53 -> 0 | I24: =-Założenia!C53 -> 0 | J24: =-Założenia!D53 -> 0 | K24: =-Założenia!E53 -> 0 | L24: =-Założenia!F53 -> 0
A25: Koszty finansowe razem | B25: =SUM(B21:B24) -> -52096 | C25: =SUM(C21:C24) -> -46703 | D25: =SUM(D21:D24) -> -141293 | E25: =SUM(E21:E24) -> -147316 | F25: =SUM(F21:F24) -> -121424 | G25: =SUM(G21:G24) -> -122945 | H25: =SUM(H21:H24) -> -104763.4 | I25: =SUM(I21:I24) -> -111044.05 | ... L25: =SUM(L21:L24) -> -152413.29
A26: Zysk przed opodatkowaniem | B26: =B18+B20+B25 -> 590854 | C26: =C18+C20+C25 -> 731066 | D26: =D18+D20+D25 -> 1101489 | E26: =E18+E20+E25 -> 1382153 | F26: =F18+F20+F25 -> 1384384 | G26: =G18+G20+G25 -> 1421622 | H26: =H18+H20+H25 -> 1922761.2 | I26: =I18+I20+I25 -> 2232566.2 | ... L26: =L18+L20+L25 -> 3264860.3
A27: Podatek dochodowy | B27: ='Dane źródłowe'!B16 -> -145083 | C27: ='Dane źródłowe'!C16 -> -173106 | D27: ='Dane źródłowe'!D16 -> -269531 | E27: ='Dane źródłowe'!E16 -> -333654 | F27: ='Dane źródłowe'!F16 -> -287834 | G27: ='Dane źródłowe'!G16 -> -367856 | H27: =-H26*Założenia!B15 -> -365324.63 | I27: =-I26*Założenia!B15 -> -424187.58 | J27: =-J26*Założenia!B15 -> -490126.89 | K27: =-K26*Założenia!B15 -> -560197.5 | L27: =-L26*Założenia!B15 -> -620323.45
A28: Zysk netto | B28: =B26+B27 -> 445771 | C28: =C26+C27 -> 557960 | D28: =D26+D27 -> 831958 | E28: =E26+E27 -> 1048499 | F28: =F26+F27 -> 1096550 | G28: =G26+G27 -> 1053766 | H28: =H26+H27 -> 1557436.6 | I28: =I26+I27 -> 1808378.6 | ... L28: =L26+L27 -> 2644536.8
A29: Marża netto | B29: =B28/B6 -> 0.044023222 | C29: =C28/C6 -> 0.041757184 | D29: =D28/D6 -> 0.042014639 | E29: =E28/E6 -> 0.040851266 | F29: =F28/F6 -> 0.03745842 | G29: =G28/G6 -> 0.031330236 | H29: =H28/H6 -> 0.038987294 | I29: =I28/I6 -> 0.038897684 | ... L29: =L28/L6 -> 0.038568228
A30: Rachunek przepływów pieniężnych
A31: Zysk netto | B31: =B28 -> 445771 | C31: =C28 -> 557960 | D31: =D28 -> 831958 | E31: =E28 -> 1048499 | F31: =F28 -> 1096550 | G31: =G28 -> 1053766 | H31: =H28 -> 1557436.6 | I31: =I28 -> 1808378.6 | ... L31: =L28 -> 2644536.8
A32: Korekta o amortyzację | B32: =-B17 -> 198146 | C32: =-C17 -> 247343 | D32: =-D17 -> 300129 | E32: =-E17 -> 356828 | F32: =-F17 -> 409179 | G32: =-G17 -> 505031 | H32: =-H17 -> 599209.29 | I32: =-I17 -> 743850.42 | ... L32: =-L17 -> 1302787.3
A33: Zmiana kapitału obrotowego netto i pozostałe pozycje operacyjne | B33: =B34-SUM(B31:B32) -> 176005 | C33: =SUM('Dane źródłowe'!C28:C31)-SUM('Dane źródłowe'!B28:B31) -> 529904 | D33: =SUM('Dane źródłowe'!D28:D31)-SUM('Dane źródłowe'!C28:C31) -> 757504 | E33: =SUM('Dane źródłowe'!E28:E31)-SUM('Dane źródłowe'!D28:D31) -> 710654 | F33: =SUM('Dane źródłowe'!F28:F31)-SUM('Dane źródłowe'!E28:E31) -> 512930 | G33: =SUM('Dane źródłowe'!G28:G31)-SUM('Dane źródłowe'!F28:F31) -> 468881 | H33: =(H90-G90) -> -347357.71 | I33: =-(I90-H90) -> 360423.34 | J33: =-(J90-I90) -> 389186.26 | K33: =-(K90-J90) -> 413821.09 | L33: =-(L90-K90) -> 431376.56
A34: Przepływy pieniężne z działalności operacyjnej | B34: ='Dane źródłowe'!B72 -> 819922 | C34: ='Dane źródłowe'!C72 -> 1326331 | D34: ='Dane źródłowe'!D72 -> 1253422 | E34: ='Dane źródłowe'!E72 -> 1771540 | F34: ='Dane źródłowe'!F72 -> 2557453 | G34: ='Dane źródłowe'!G72 -> 2697445 | H34: =SUM(H31:H33) -> 1809288.1 | I34: =SUM(I31:I33) -> 2912652.4 | J34: =SUM(J31:J33) -> 3388388.8 | K34: =SUM(K31:K33) -> 3898491.8 | L34: =SUM(L31:L33) -> 4378700.7
A35: Nakłady inwestycyjne | B35: ='Dane źródłowe'!B74 -> -1002025 | C35: ='Dane źródłowe'!C74 -> -1335604 | D35: ='Dane źródłowe'!D74 -> -1445905 | E35: ='Dane źródłowe'!E74 -> -1172863 | F35: ='Dane źródłowe'!F74 -> -1561914 | G35: ='Dane źródłowe'!G74 -> -2087043 | H35: =-H6*Założenia!B32 -> -2436784.4 | I35: =-I6*Założenia!C32 -> -2742948.4 | J35: =-J6*Założenia!D32 -> -3050218.2 | K35: =-K6*Założenia!E32 -> -3350295.4 | L35: =-L6*Założenia!F32 -> -3634091
A36: Pozostała działalność inwestycyjna | B36: ='Dane źródłowe'!B79-B35 -> 1889 | C36: ='Dane źródłowe'!C79-C35 -> 4876 | D36: ='Dane źródłowe'!D79-D35 -> 11342 | E36: ='Dane źródłowe'!E79-E35 -> 14607 | F36: ='Dane źródłowe'!F79-F35 -> -34995 | G36: ='Dane źródłowe'!G79-G35 -> 11989 | H36: =Założenia!B56 -> 0 | I36: =Założenia!C56 -> 0 | J36: =Założenia!D56 -> 0 | K36: =Założenia!E56 -> 0 | L36: =Założenia!F56 -> 0
A37: Przepływy pieniężne z działalności inwestycyjnej | B37: =SUM(B35:B36) -> -1000136 | C37: =SUM(C35:C36) -> -1330728 | D37: =SUM(D35:D36) -> -1434563 | E37: =SUM(E35:E36) -> -1158256 | F37: =SUM(F35:F36) -> -1596909 | G37: =SUM(G35:G36) -> -2075054 | H37: =SUM(H35:H36) -> -2436784.4 | I37: =SUM(I35:I36) -> -2742948.4 | ... L37: =SUM(L35:L36) -> -3634091
A38: Zmiana netto długu / leasingu / obligacji | B38: =SUM('Dane źródłowe'!B80:B85) -> 265912 | C38: =SUM('Dane źródłowe'!C80:C85) -> -57406 | D38: =SUM('Dane źródłowe'!D80:D85) -> 145244 | E38: =SUM('Dane źródłowe'!E80:E85) -> -777613 | F38: =SUM('Dane źródłowe'!F80:F85) -> -287911 | G38: =SUM('Dane źródłowe'!G80:G85) -> -558599 | H38: =Założenia!B44+Założenia!B46+Założenia!B48 -> -149993.37 | I38: =Założenia!C44+Założenia!C46+Założenia!C48 -> 23007.293 | J38: =Założenia!D44+Założenia!D46+Założenia!D48 -> 25977.949 | K38: =Założenia!E44+Założenia!E46+Założenia!E48 -> 28856.185 | L38: =Założenia!F44+Założenia!F46+Założenia!F48 -> 31576.118
A39: Dywidendy / wypłaty | B39: =0 -> 0 | C39: =0 -> 0 | D39: =0 -> 0 | E39: =0 -> 0 | F39: =0 -> 0 | G39: =0 -> 0 | H39: =Założenia!B55 -> 0 | I39: =Założenia!C55 -> 0 | J39: =Założenia!D55 -> 0 | K39: =Założenia!E55 -> 0 | L39: =Założenia!F55 -> 0
A40: Pozostałe finansowanie / pozycja bilansująca | B40: ='Dane źródłowe'!B86-B38-B39 -> 0 | C40: ='Dane źródłowe'!C86-C38-C39 -> 0 | D40: ='Dane źródłowe'!D86-D38-D39 -> 0 | E40: ='Dane źródłowe'!E86-E38-E39 -> 0 | F40: ='Dane źródłowe'!F86-F38-F39 -> 0 | G40: ='Dane źródłowe'!G86-G38-G39 -> 0 | H40: =Założenia!B54 -> 0 | I40: =Założenia!C54 -> 0 | J40: =Założenia!D54 -> 0 | K40: =Założenia!E54 -> 0 | L40: =Założenia!F54 -> 0
...

Sheet Dług i WACC
A1: Harmonogram długu i WACC
A2: Prognozowany WACC wykorzystuje jawnie określoną docelową strukturę kapitału. Kapitalizacja rynkowa jest pokazana wyłącznie referencyjnie i nie wpływa na wagi WACC.
A3: Miara | B3: 2020 | C3: 2021 | D3: 2022 | E3: 2023 | F3: 2024 | G3: 2025 | H3: 2026 | I3: 2027 | J3: 2028 | K3: 2029 | L3: 2030
A4: Okres | B4: 2020A | C4: 2021A | D4: 2022A | E4: 2023A | F4: 2024A | G4: 2025A | H4: 2026E | I4: 2027E | J4: 2028E | K4: 2029E | L4: 2030E
A5: Harmonogram długu
A6: Kredyty bankowe (długoterminowe) | B6: ='Dane źródłowe'!B43 -> 725851 | C6: ='Dane źródłowe'!C43 -> 583014 | D6: ='Dane źródłowe'!D43 -> 690862 | E6: ='Dane źródłowe'!E43 -> 469629 | F6: ='Dane źródłowe'!F43 -> 272219 | G6: ='Dane źródłowe'!G43 -> 312861 | H6: =(G6+G7+Założenia!B44)*(1-Założenia!B45) -> 310067.29 | I6: =(H6+H7+Założenia!C44)*(1-Założenia!C45) -> 303367.29 | J6: =(I6+I7+Założenia!D44)*(1-Założenia!D45) -> 296667.29 | K6: =(J6+J7+Założenia!E44)*(1-Założenia!E45) -> 289967.29 | L6: =(K6+K7+Założenia!F44)*(1-Założenia!F45) -> 283267.29
A7: Kredyty bankowe (krótkoterminowe) | B7: ='Dane źródłowe'!B53 -> 216868 | C7: ='Dane źródłowe'!C53 -> 196169 | D7: ='Dane źródłowe'!D53 -> 410157 | E7: ='Dane źródłowe'!E53 -> 278588 | F7: ='Dane źródłowe'!F53 -> 361034 | G7: ='Dane źródłowe'!G53 -> 159926 | H7: =(G6+G7+Założenia!B44)*Założenia!B45 -> 152719.71 | I7: =(H6+H7+Założenia!C44)*Założenia!C45 -> 149419.71 | J7: =(I6+I7+Założenia!D44)*Założenia!D45 -> 146119.71 | K7: =(J6+J7+Założenia!E44)*Założenia!E45 -> 142819.71 | L7: =(K6+K7+Założenia!F44)*Założenia!F45 -> 139519.71
A8: Zobowiązania leasingowe (długoterminowe) | B8: ='Dane źródłowe'!B44 -> 67876 | C8: ='Dane źródłowe'!C44 -> 46621 | D8: ='Dane źródłowe'!D44 -> 34673 | E8: ='Dane źródłowe'!E44 -> 35612 | F8: ='Dane źródłowe'!F44 -> 60818 | G8: ='Dane źródłowe'!G44 -> 87851 | H8: =(G8+G9+Założenia!B46)*(1-Założenia!B47) -> 111129.01 | I8: =(H8+H9+Założenia!C46)*(1-Założenia!C47) -> 137204.77 | J8: =(I8+I9+Założenia!D46)*(1-Założenia!D47) -> 165627.35 | K8: =(J8+J9+Założenia!E46)*(1-Założenia!E47) -> 196323.74 | L8: =(K8+K9+Założenia!F46)*(1-Założenia!F47) -> 229168.87
A9: Zobowiązania leasingowe (krótkoterminowe) | B9: ='Dane źródłowe'!B54 -> 42249 | C9: ='Dane źródłowe'!C54 -> 27721 | D9: ='Dane źródłowe'!D54 -> 17893 | E9: ='Dane źródłowe'!E54 -> 14565 | F9: ='Dane źródłowe'!F54 -> 17900 | G9: ='Dane źródłowe'!G54 -> 22812 | H9: =(G8+G9+Założenia!B46)*Założenia!B47 -> 29540.622 | I9: =(H8+H9+Założenia!C46)*Założenia!C47 -> 36472.154 | J9: =(I8+I9+Założenia!D46)*Założenia!D47 -> 44027.523 | K9: =(J8+J9+Założenia!E46)*Założenia!E47 -> 52187.322 | L9: =(K8+K9+Założenia!F46)*Założenia!F47 -> 60918.307
A10: Obligacje (długoterminowe) | B10: ='Dane źródłowe'!B45 -> 419936 | C10: ='Dane źródłowe'!C45 -> 450000 | D10: ='Dane źródłowe'!D45 -> 370000 | E10: ='Dane źródłowe'!E45 -> 370000 | F10: ='Dane źródłowe'!F45 -> 170000 | G10: ='Dane źródłowe'!G45 -> 0 | H10: =(G10+G11+Założenia!B48)*(1-Założenia!B49) -> 1411.5 | I10: =(H10+H11+Założenia!C48)*(1-Założenia!C49) -> 1411.5 | J10: =(I10+I11+Założenia!D48)*(1-Założenia!D49) -> 1411.5 | K10: =(J10+J11+Założenia!E48)*(1-Założenia!E49) -> 1411.5 | L10: =(K10+K11+Założenia!F48)*(1-Założenia!F49) -> 1411.5
A11: Obligacje (krótkoterminowe) | B11: ='Dane źródłowe'!B55 -> 930 | C11: ='Dane źródłowe'!C55 -> 171642 | D11: ='Dane źródłowe'!D55 -> 260947 | E11: ='Dane źródłowe'!E55 -> 4784 | F11: ='Dane źródłowe'!F55 -> 204845 | G11: ='Dane źródłowe'!G55 -> 171882 | H11: =(G10+G11+Założenia!B48)*Założenia!B49 -> 470.5 | I11: =(H10+H11+Założenia!C48)*Założenia!C49 -> 470.5 | J11: =(I10+I11+Założenia!D48)*Założenia!D49 -> 470.5 | K11: =(J10+J11+Założenia!E48)*Założenia!E49 -> 470.5 | L11: =(K10+K11+Założenia!F48)*Założenia!F49 -> 470.5
A12: Dług oprocentowany razem | B12: =SUM(B6:B11) -> 1473710 | C12: =SUM(C6:C11) -> 1475167 | D12: =SUM(D6:D11) -> 1784532 | E12: =SUM(E6:E11) -> 1173178 | F12: =SUM(F6:F11) -> 1086816 | G12: =SUM(G6:G11) -> 755332 | H12: =SUM(H6:H11) -> 605338.63 | I12: =SUM(I6:I11) -> 628345.92 | ... L12: =SUM(L6:L11) -> 714756.18
A13: Środki pieniężne i ich ekwiwalenty | B13: ='Model 3 sprawozdań'!B56 -> 480418 | C13: ='Model 3 sprawozdań'!C56 -> 418615 | D13: ='Model 3 sprawozdań'!D56 -> 382718 | E13: ='Model 3 sprawozdań'!E56 -> 218389 | F13: ='Model 3 sprawozdań'!F56 -> 891022 | G13: ='Model 3 sprawozdań'!G56 -> 954814 | H13: ='Model 3 sprawozdań'!H56 -> 177324.33 | I13: ='Model 3 sprawozdań'!I56 -> 370035.6 | ... L13: ='Model 3 sprawozdań'!L56 -> 2087422.5
A14: Dług netto | B14: =B12-B13 -> 993292 | C14: =C12-C13 -> 1056552 | D14: =D12-D13 -> 1401814 | E14: =E12-E13 -> 954789 | F14: =F12-F13 -> 195794 | G14: =G12-G13 -> -199482 | H14: =H12-H13 -> 428014.3 | I14: =I12-I13 -> 258310.32 | ... L14: =L12-L13 -> -1372666.4
A15: Średni dług razem | B15: =B12 -> 1473710 | C15: =AVERAGE(B12,C12) -> 1474438.5 | D15: =AVERAGE(C12,D12) -> 1629849.5 | E15: =AVERAGE(D12,E12) -> 1478855 | F15: =AVERAGE(E12,F12) -> 1129997 | G15: =AVERAGE(F12,G12) -> 921074 | H15: =AVERAGE(G12,H12) -> 680335.31 | I15: =AVERAGE(H12,I12) -> 616842.28 | J15: =AVERAGE(I12,J12) -> 641334.9 | ... L15: =AVERAGE(K12,L12) -> 698968.12
A16: Podział odsetek od zobowiązań
A17: Łączne koszty odsetkowe finansowe | B17: =-'Dane źródłowe'!B14 -> 52096 | C17: =-'Dane źródłowe'!C14 -> 46703 | D17: =-'Dane źródłowe'!D14 -> 141293 | E17: =-'Dane źródłowe'!E14 -> 147316 | F17: =-'Dane źródłowe'!F14 -> 121424 | G17: =-'Dane źródłowe'!G14 -> 122945 | H17: =H20+H18+H19 -> 104763.4 | I17: =I20+I18+I19 -> 111044.05 | J17: =J20+J18+J19 -> 123874.84 | K17: =K20+K18+K19 -> 137723.38 | L17: =L20+L18+L19 -> 152413.29
A18: Koszty odsetkowe - zobowiązania handlowe | B18: 18139 | C18: 20434 | D18: 15839 | E18: 19600 | F18: 29836 | G18: 54614 | H18: ='Model 3 sprawozdań'!G75*Założenia!B51 -> 57139.929 | I18: ='Model 3 sprawozdań'!H75*Założenia!C51 -> 67865.094 | J18: ='Model 3 sprawozdań'!I75*Założenia!D51 -> 78981.396 | K18: ='Model 3 sprawozdań'!J75*Założenia!E51 -> 90910.746 | L18: ='Model 3 sprawozdań'!K75*Założenia!F51 -> 103485.52
A19: Koszty odsetkowe - pozostałe | B19: =-SUM('Model 3 sprawozdań'!B23,'Model 3 sprawozdań'!B24) -> 3578 | C19: =-SUM('Model 3 sprawozdań'!C23,'Model 3 sprawozdań'!C24) -> 114 | D19: =-SUM('Model 3 sprawozdań'!D23,'Model 3 sprawozdań'!D24) -> 622 | E19: =-SUM('Model 3 sprawozdań'!E23,'Model 3 sprawozdań'!E24) -> 431 | F19: =-SUM('Model 3 sprawozdań'!F23,'Model 3 sprawozdań'!F24) -> 631 | G19: =-SUM('Model 3 sprawozdań'!G23,'Model 3 sprawozdań'!G24) -> 385 | H19: 0 | I19: 0 | J19: 0 | K19: 0 | L19: 0
A20: Koszty odsetkowe - dług / leasingi / obligacje | B20: =B17-B18-B19 -> 30379 | C20: =C17-C18-C19 -> 26155 | D20: =D17-D18-D19 -> 124832 | E20: =E17-E18-E19 -> 127285 | F20: =F17-F18-F19 -> 90957 | G20: =G17-G18-G19 -> 67946 | H20: =H15*Założenia!B50 -> 47623.472 | I20: =I15*Założenia!C50 -> 43178.959 | J20: =J15*Założenia!D50 -> 44893.443 | K20: =K15*Założenia!E50 -> 46812.638 | L20: =L15*Założenia!F50 -> 48927.768
A21: Koszt długu przed opodatkowaniem | B21: =B20/B15 -> 0.020613961 | C21: =C20/C15 -> 0.017738956 | D21: =D20/D15 -> 0.076591121 | E21: =E20/E15 -> 0.086069966 | F21: =F20/F15 -> 0.080493134 | G21: =G20/G15 -> 0.073768231 | H21: =H20/H15 -> 0.07 | I21: =I20/I15 -> 0.07 | ... L21: =L20/L15 -> 0.07
A22: Kalkulacja WACC
A23: Referencyjna cena rynkowa / akcję (PLN) | B23: =Założenia!B20 -> 200 | C23: =Założenia!C20 -> 300 | D23: =Założenia!D20 -> 330 | E23: =Założenia!E20 -> 420 | F23: =Założenia!F20 -> 400 | G23: =Założenia!G20 -> 41 | H23: =(H25-H14)/Założenia!$B$10 -> 39.459965 | I23: =(I25-I14)/Założenia!$B$10 -> 46.920036 | J23: =(J25-J14)/Założenia!$B$10 -> 55.249809 | K23: =(K25-K14)/Założenia!$B$10 -> 64.409094 | L23: =(L25-L14)/Założenia!$B$10 -> 73.215227
A24: Liczba akcji (tys.) | B24: =Założenia!B22 -> 98040 | C24: =Założenia!C22 -> 98040 | D24: =Założenia!D22 -> 98040 | E24: =Założenia!E22 -> 98040 | F24: =Założenia!F22 -> 98040 | G24: =Założenia!G22 -> 980400 | H24: =Założenia!B10 -> 980400 | I24: =Założenia!B10 -> 980400 | J24: =Założenia!B10 -> 980400 | K24: =Założenia!B10 -> 980400 | L24: =Założenia!B10 -> 980400
A25: Referencyjna kapitalizacja rynkowa | B25: =B23*B24 -> 19608000 | C25: =C23*C24 -> 29412000 | D25: =D23*D24 -> 32353200 | E25: =E23*E24 -> 41176800 | F25: =F23*F24 -> 39216000 | G25: =G23*G24 -> 40196400 | H25: =Założenia!$B$4*'Model 3 sprawozdań'!H15 -> 39114564 | I25: =Założenia!$B$4*'Model 3 sprawozdań'!I15 -> 46258713 | J25: =Założenia!$B$4*'Model 3 sprawozdań'!J15 -> 54087053 | K25: =Założenia!$B$4*'Model 3 sprawozdań'!K15 -> 62518619 | L25: =Założenia!$B$4*'Model 3 sprawozdań'!L15 -> 70407542
A26: Dług oprocentowany razem | B26: =B12 -> 1473710 | C26: =C12 -> 1475167 | D26: =D12 -> 1784532 | E26: =E12 -> 1173178 | F26: =F12 -> 1086816 | G26: =G12 -> 755332 | H26: =H12 -> 605338.63 | I26: =I12 -> 628345.92 | ... L26: =L12 -> 714756.18
A27: Środki pieniężne i ich ekwiwalenty | B27: =B13 -> 480418 | C27: =C13 -> 418615 | D27: =D13 -> 382718 | E27: =E13 -> 218389 | F27: =F13 -> 891022 | G27: =G13 -> 954814 | H27: =H13 -> 177324.33 | I27: =I13 -> 370035.6 | ... L27: =L13 -> 2087422.5
A28: Dług netto | B28: =B14 -> 993292 | C28: =C14 -> 1056552 | D28: =D14 -> 1401814 | E28: =E14 -> 954789 | F28: =F14 -> 195794 | G28: =G14 -> -199482 | H28: =H14 -> 428014.3 | I28: =I14 -> 258310.32 | ... L28: =L14 -> -1372666.4
A29: Wartość przedsiębiorstwa | B29: =B25+B28 -> 20601292 | C29: =C25+C28 -> 30468552 | D29: =D25+D28 -> 33755014 | E29: =E25+E28 -> 42131589 | F29: =F25+F28 -> 39411794 | G29: =G25+G28 -> 39996918 | H29: =H25+H28 -> 39542578 | I29: =I25+I28 -> 46517024 | ... L29: =L25+L28 -> 69034876
A30: Stawka podatkowa | B30: =-'Dane źródłowe'!B16/'Dane źródłowe'!B15 -> 0.18388213 | C30: =-'Dane źródłowe'!C16/'Dane źródłowe'!C15 -> 0.17692601 | D30: =-'Dane źródłowe'!D16/'Dane źródłowe'!D15 -> 0.1922999 | E30: =-'Dane źródłowe'!E16/'Dane źródłowe'!E15 -> 0.19186754 | F30: =-'Dane źródłowe'!F16/'Dane źródłowe'!F15 -> 0.16048168 | G30: =-'Dane źródłowe'!G16/'Dane źródłowe'!G15 -> 0.19093007 | H30: =Założenia!B15 -> 0.19 | I30: =Założenia!B15 -> 0.19 | J30: =Założenia!B15 -> 0.19 | K30: =Założenia!B15 -> 0.19 | L30: =Założenia!B15 -> 0.19
A31: Koszt długu po opodatkowaniu | B31: =B21*(1-B30) -> 0.016823422 | C31: =C21*(1-C30) -> 0.014600473 | D31: =D21*(1-D30) -> 0.061862656 | E31: =E21*(1-E30) -> 0.069555934 | F31: =F21*(1-F30) -> 0.067575461 | G31: =G21*(1-G30) -> 0.059683658 | H31: =H21*(1-H30) -> 0.0567 | I31: =I21*(1-I30) -> 0.0567 | ... L31: =L21*(1-L30) -> 0.0567
A32: Stopa wolna od ryzyka | B32: =Założenia!B21 -> 0.015 | C32: =Założenia!C21 -> 0.0194 | D32: =Założenia!D21 -> 0.0605 | E32: =Założenia!E21 -> 0.0581 | F32: =Założenia!F21 -> 0.0553 | G32: =Założenia!G21 -> 0.055 | H32: =Założenia!B5 -> 0.0588 | I32: =Założenia!B5 -> 0.0588 | J32: =Założenia!B5 -> 0.0588 | K32: =Założenia!B5 -> 0.0588 | L32: =Założenia!B5 -> 0.0588
A33: Beta | B33: =Założenia!B6 -> 0.51 | C33: =Założenia!B6 -> 0.51 | D33: =Założenia!B6 -> 0.51 | E33: =Założenia!B6 -> 0.51 | F33: =Założenia!B6 -> 0.51 | G33: =Założenia!B6 -> 0.51 | H33: =Założenia!B6 -> 0.51 | I33: =Założenia!B6 -> 0.51 | J33: =Założenia!B6 -> 0.51 | K33: =Założenia!B6 -> 0.51 | L33: =Założenia!B6 -> 0.51
A34: Premia za ryzyko kapitału własnego | B34: =Założenia!B7 -> 0.0533 | C34: =Założenia!B7 -> 0.0533 | D34: =Założenia!B7 -> 0.0533 | E34: =Założenia!B7 -> 0.0533 | F34: =Założenia!B7 -> 0.0533 | G34: =Założenia!B7 -> 0.0533 | H34: =Założenia!B7 -> 0.0533 | I34: =Założenia!B7 -> 0.0533 | J34: =Założenia!B7 -> 0.0533 | K34: =Założenia!B7 -> 0.0533 | L34: =Założenia!B7 -> 0.0533
A35: Koszt kapitału własnego | B35: =B32+B33*B34 -> 0.042183 | C35: =C32+C33*C34 -> 0.046583 | D35: =D32+D33*D34 -> 0.087683 | E35: =E32+E33*E34 -> 0.085283 | F35: =F32+F33*F34 -> 0.082483 | G35: =G32+G33*G34 -> 0.082183 | H35: =H32+H33*H34 -> 0.085983 | I35: =I32+I33*I34 -> 0.085983 | ... L35: =L32+L33*L34 -> 0.085983
A36: Docelowy udział kapitału własnego / faktyczny udział kapitału własnego | B36: ='Model 3 sprawozdań'!B65/('Model 3 sprawozdań'!B65+B12) -> 0.60598865 | C36: ='Model 3 sprawozdań'!C65/('Model 3 sprawozdań'!C65+C12) -> 0.6754563 | D36: ='Model 3 sprawozdań'!D65/('Model 3 sprawozdań'!D65+D12) -> 0.70199764 | E36: ='Model 3 sprawozdań'!E65/('Model 3 sprawozdań'!E65+E12) -> 0.82692633 | F36: ='Model 3 sprawozdań'!F65/('Model 3 sprawozdań'!F65+F12) -> 0.86728748 | G36: ='Model 3 sprawozdań'!G65/('Model 3 sprawozdań'!G65+G12) -> 0.91987096 | H36: =Założenia!B16 -> 0.95 | I36: =Założenia!B16 -> 0.95 | J36: =Założenia!B16 -> 0.95 | K36: =Założenia!B16 -> 0.95 | L36: =Założenia!B16 -> 0.95
A37: Docelowy udział długu / faktyczny udział długu | B37: =1-B36 -> 0.39401135 | C37: =1-C36 -> 0.3245437 | D37: =1-D36 -> 0.29800236 | E37: =1-E36 -> 0.17307367 | F37: =1-F36 -> 0.13271252 | G37: =1-G36 -> 0.080129041 | H37: =Założenia!B17 -> 0.05 | I37: =Założenia!B17 -> 0.05 | J37: =Założenia!B17 -> 0.05 | K37: =Założenia!B17 -> 0.05 | L37: =Założenia!B17 -> 0.05
A38: WACC | B38: =B35*B36+B31*B37 -> 0.032191038 | C38: =C35*C36+C31*C37 -> 0.036203272 | D38: =D35*D36+D31*D37 -> 0.079988477 | E38: =E35*E36+E31*E37 -> 0.082561059 | F38: =F35*F36+F31*F37 -> 0.080504583 | G38: =G35*G36+G31*G37 -> 0.080380149 | H38: =H35*H36+H31*H37 -> 0.08451885 | I38: =I35*I36+I31*I37 -> 0.08451885 | ... L38: =L35*L36+L31*L37 -> 0.08451885

Sheet Wycena DCF
A1: Wycena DCF | I1: Analiza wrażliwości — implikowana wartość / akcję (PLN)
A2: Nominalny nielewarowany DCF z dwoma scenariuszami nakładów inwestycyjnych. Scenariusz 1 zakłada dalszy wzrost nakładów inwestycyjnych; Scenariusz 2 zakłada, że nakłady inwestycyjne w roku rezydualnym są równe amortyzacji. | I2: Wiersze = wzrost rezydualny; kolumny = WACC. Formuły odwołują się do istniejącego DCF i nie zmieniają założeń modelu.
A3: Miara | B3: 2026E | C3: 2027E | D3: 2028E | E3: 2029E | F3: 2030E | G3: Rezydualny
A4: Kluczowe założenia wyceny | I4: Scenariusz 1: dalszy wzrost nakładów inwestycyjnych
A5: WACC | B5: ='Dług i WACC'!H38 -> 0.08451885 | I5: g \ WACC | J5: =$B$5-1% -> 0.07451885 | K5: =$B$5-0.5% -> 0.07951885 | L5: =$B$5 -> 0.08451885 | M5: =$B$5+0.5% -> 0.08951885 | N5: =$B$5+1% -> 0.09451885
A6: Stopa wzrostu rezydualnego | B6: =Założenia!B8 -> 0.03 | I6: =$B$6-1% -> 0.02 | J6: =IF(J$5>$I6,((SUMPRODUCT($B$14:$F$14,1/(1+J$5)^$B$16:$F$16)+($F$14*(1+$I6)/(J$5-$I6))/(1+J$5)^$F$16)-$B$23)/$B$25,NA()) -> 13.295932 | K6: =IF(K$5>$I6,((SUMPRODUCT($B$14:$F$14,1/(1+K$5)^$B$16:$F$16)+($F$14*(1+$I6)/(K$5-$I6))/(1+K$5)^$F$16)-$B$23)/$B$25,NA()) -> 12.080513 | L6: =IF(L$5>$I6,((SUMPRODUCT($B$14:$F$14,1/(1+L$5)^$B$16:$F$16)+($F$14*(1+$I6)/(L$5-$I6))/(1+L$5)^$F$16)-$B$23)/$B$25,NA()) -> 11.055445 | M6: =IF(M$5>$I6,((SUMPRODUCT($B$14:$F$14,1/(1+M$5)^$B$16:$F$16)+($F$14*(1+$I6)/(M$5-$I6))/(1+M$5)^$F$16)-$B$23)/$B$25,NA()) -> 10.179613 | N6: =IF(N$5>$I6,((SUMPRODUCT($B$14:$F$14,1/(1+N$5)^$B$16:$F$16)+($F$14*(1+$I6)/(N$5-$I6))/(1+N$5)^$F$16)-$B$23)/$B$25,NA()) -> 9.4229381
A7: Nielewarowane wolne przepływy pieniężne | I7: =$B$6-0.5% -> 0.025 | J7: =IF(J$5>$I7,((SUMPRODUCT($B$14:$F$14,1/(1+J$5)^$B$16:$F$16)+($F$14*(1+$I7)/(J$5-$I7))/(1+J$5)^$F$16)-$B$23)/$B$25,NA()) -> 14.495944 | K7: =IF(K$5>$I7,((SUMPRODUCT($B$14:$F$14,1/(1+K$5)^$B$16:$F$16)+($F$14*(1+$I7)/(K$5-$I7))/(1+K$5)^$F$16)-$B$23)/$B$25,NA()) -> 13.060537 | L7: =IF(L$5>$I7,((SUMPRODUCT($B$14:$F$14,1/(1+L$5)^$B$16:$F$16)+($F$14*(1+$I7)/(L$5-$I7))/(1+L$5)^$F$16)-$B$23)/$B$25,NA()) -> 11.868406 | M7: =IF(M$5>$I7,((SUMPRODUCT($B$14:$F$14,1/(1+M$5)^$B$16:$F$16)+($F$14*(1+$I7)/(M$5-$I7))/(1+M$5)^$F$16)-$B$23)/$B$25,NA()) -> 10.862944 | N7: =IF(N$5>$I7,((SUMPRODUCT($B$14:$F$14,1/(1+N$5)^$B$16:$F$16)+($F$14*(1+$I7)/(N$5-$I7))/(1+N$5)^$F$16)-$B$23)/$B$25,NA()) -> 10.003833
A8: EBIT | B8: ='Model 3 sprawozdań'!H18 -> 2008428.3 | C8: ='Model 3 sprawozdań'!I18 -> 2340063.8 | D8: ='Model 3 sprawozdań'!J18 -> 2696089.3 | E8: ='Model 3 sprawozdań'!K18 -> 3071447.6 | F8: ='Model 3 sprawozdań'!L18 -> 3391048.8 | I8: =$B$6 -> 0.03 | J8: =IF(J$5>$I8,((SUMPRODUCT($B$14:$F$14,1/(1+J$5)^$B$16:$F$16)+($F$14*(1+$I8)/(J$5-$I8))/(1+J$5)^$F$16)-$B$23)/$B$25,NA()) -> 15.965508 | K8: =IF(K$5>$I8,((SUMPRODUCT($B$14:$F$14,1/(1+K$5)^$B$16:$F$16)+($F$14*(1+$I8)/(K$5-$I8))/(1+K$5)^$F$16)-$B$23)/$B$25,NA()) -> 14.238471 | L8: =IF(L$5>$I8,((SUMPRODUCT($B$14:$F$14,1/(1+L$5)^$B$16:$F$16)+($F$14*(1+$I8)/(L$5-$I8))/(1+L$5)^$F$16)-$B$23)/$B$25,NA()) -> 12.830482 | M8: =IF(M$5>$I8,((SUMPRODUCT($B$14:$F$14,1/(1+M$5)^$B$16:$F$16)+($F$14*(1+$I8)/(M$5-$I8))/(1+M$5)^$F$16)-$B$23)/$B$25,NA()) -> 11.661084 | N8: =IF(N$5>$I8,((SUMPRODUCT($B$14:$F$14,1/(1+N$5)^$B$16:$F$16)+($F$14*(1+$I8)/(N$5-$I8))/(1+N$5)^$F$16)-$B$23)/$B$25,NA()) -> 10.674762
A9: Podatki gotówkowe od EBIT | B9: =-B8*Założenia!B15 -> -381601.38 | C9: =-C8*Założenia!B15 -> -444612.12 | D9: =-D8*Założenia!B15 -> -512256.97 | E9: =-E8*Założenia!B15 -> -583575.04 | F9: =-F8*Założenia!B15 -> -644299.28 | I9: =$B$6+0.5% -> 0.035 | J9: =IF(J$5>$I9,((SUMPRODUCT($B$14:$F$14,1/(1+J$5)^$B$16:$F$16)+($F$14*(1+$I9)/(J$5-$I9))/(1+J$5)^$F$16)-$B$23)/$B$25,NA()) -> 17.806935 | K9: =IF(K$5>$I9,((SUMPRODUCT($B$14:$F$14,1/(1+K$5)^$B$16:$F$16)+($F$14*(1+$I9)/(K$5-$I9))/(1+K$5)^$F$16)-$B$23)/$B$25,NA()) -> 15.680997 | L9: =IF(L$5>$I9,((SUMPRODUCT($B$14:$F$14,1/(1+L$5)^$B$16:$F$16)+($F$14*(1+$I9)/(L$5-$I9))/(1+L$5)^$F$16)-$B$23)/$B$25,NA()) -> 13.986843 | M9: =IF(M$5>$I9,((SUMPRODUCT($B$14:$F$14,1/(1+M$5)^$B$16:$F$16)+($F$14*(1+$I9)/(M$5-$I9))/(1+M$5)^$F$16)-$B$23)/$B$25,NA()) -> 12.60562 | N9: =IF(N$5>$I9,((SUMPRODUCT($B$14:$F$14,1/(1+N$5)^$B$16:$F$16)+($F$14*(1+$I9)/(N$5-$I9))/(1+N$5)^$F$16)-$B$23)/$B$25,NA()) -> 11.458417
A10: NOPAT | B10: =B8+B9 -> 1626826.9 | C10: =C8+C9 -> 1895451.7 | D10: =D8+D9 -> 2183832.4 | E10: =E8+E9 -> 2487872.5 | F10: =F8+F9 -> 2746749.5 | I10: =$B$6+1% -> 0.04 | J10: =IF(J$5>$I10,((SUMPRODUCT($B$14:$F$14,1/(1+J$5)^$B$16:$F$16)+($F$14*(1+$I10)/(J$5-$I10))/(1+J$5)^$F$16)-$B$23)/$B$25,NA()) -> 20.181819 | K10: =IF(K$5>$I10,((SUMPRODUCT($B$14:$F$14,1/(1+K$5)^$B$16:$F$16)+($F$14*(1+$I10)/(K$5-$I10))/(1+K$5)^$F$16)-$B$23)/$B$25,NA()) -> 17.488545 | L10: =IF(L$5>$I10,((SUMPRODUCT($B$14:$F$14,1/(1+L$5)^$B$16:$F$16)+($F$14*(1+$I10)/(L$5-$I10))/(1+L$5)^$F$16)-$B$23)/$B$25,NA()) -> 15.40295 | M10: =IF(M$5>$I10,((SUMPRODUCT($B$14:$F$14,1/(1+M$5)^$B$16:$F$16)+($F$14*(1+$I10)/(M$5-$I10))/(1+M$5)^$F$16)-$B$23)/$B$25,NA()) -> 13.7409 | N10: =IF(N$5>$I10,((SUMPRODUCT($B$14:$F$14,1/(1+N$5)^$B$16:$F$16)+($F$14*(1+$I10)/(N$5-$I10))/(1+N$5)^$F$16)-$B$23)/$B$25,NA()) -> 12.385812
A11: Korekta o amortyzację | B11: ='Model 3 sprawozdań'!H32 -> 599209.29 | C11: ='Model 3 sprawozdań'!I32 -> 743850.42 | D11: ='Model 3 sprawozdań'!J32 -> 909714.19 | E11: ='Model 3 sprawozdań'!K32 -> 1096460.3 | F11: ='Model 3 sprawozdań'!L32 -> 1302787.3
A12: Nakłady inwestycyjne | B12: ='Model 3 sprawozdań'!H35 -> -2436784.4 | C12: ='Model 3 sprawozdań'!I35 -> -2742948.4 | D12: ='Model 3 sprawozdań'!J35 -> -3050218.2 | E12: ='Model 3 sprawozdań'!K35 -> -3350295.4 | F12: ='Model 3 sprawozdań'!L35 -> -3634091 | I12: Scenariusz 2: nakłady inwestycyjne w roku rezydualnym = amortyzacja
A13: Mniej: zmiana operacyjnego kapitału obrotowego netto | B13: ='Model 3 sprawozdań'!H90-'Model 3 sprawozdań'!G90 -> -347357.71 | C13: ='Model 3 sprawozdań'!I90-'Model 3 sprawozdań'!H90 -> -360423.34 | D13: ='Model 3 sprawozdań'!J90-'Model 3 sprawozdań'!I90 -> -389186.26 | E13: ='Model 3 sprawozdań'!K90-'Model 3 sprawozdań'!J90 -> -413821.09 | F13: ='Model 3 sprawozdań'!L90-'Model 3 sprawozdań'!K90 -> -431376.56 | I13: g \ WACC | J13: =$B$5-1% -> 0.07451885 | K13: =$B$5-0.5% -> 0.07951885 | L13: =$B$5 -> 0.08451885 | M13: =$B$5+0.5% -> 0.08951885 | N13: =$B$5+1% -> 0.09451885
A14: Nielewarowane wolne przepływy pieniężne | B14: =SUM(B10:B12)-B13 -> 136609.49 | C14: =SUM(C10:C12)-C13 -> 256777.01 | D14: =SUM(D10:D12)-D13 -> 432514.65 | E14: =SUM(E10:E12)-E13 -> 647858.54 | F14: =SUM(F10:F12)-F13 -> 846822.43 | I14: =$B$6-1% -> 0.02 | J14: =IF(J$13>$I14,((SUMPRODUCT($B$14:$F$14,1/(1+J$13)^$B$16:$F$16)+($B$34*(1+$I14)/(J$13-$I14))/(1+J$13)^$F$16)-$B$23)/$B$25,NA()) -> 44.354314 | K14: =IF(K$13>$I14,((SUMPRODUCT($B$14:$F$14,1/(1+K$13)^$B$16:$F$16)+($B$34*(1+$I14)/(K$13-$I14))/(1+K$13)^$F$16)-$B$23)/$B$25,NA()) -> 39.877007 | L14: =IF(L$13>$I14,((SUMPRODUCT($B$14:$F$14,1/(1+L$13)^$B$16:$F$16)+($B$34*(1+$I14)/(L$13-$I14))/(1+L$13)^$F$16)-$B$23)/$B$25,NA()) -> 36.112128 | M14: =IF(M$13>$I14,((SUMPRODUCT($B$14:$F$14,1/(1+M$13)^$B$16:$F$16)+($B$34*(1+$I14)/(M$13-$I14))/(1+M$13)^$F$16)-$B$23)/$B$25,NA()) -> 32.905425 | N14: =IF(N$13>$I14,((SUMPRODUCT($B$14:$F$14,1/(1+N$13)^$B$16:$F$16)+($B$34*(1+$I14)/(N$13-$I14))/(1+N$13)^$F$16)-$B$23)/$B$25,NA()) -> 30.144064
A15: Dyskontowanie | I15: =$B$6-0.5% -> 0.025 | J15: =IF(J$13>$I15,((SUMPRODUCT($B$14:$F$14,1/(1+J$13)^$B$16:$F$16)+($B$34*(1+$I15)/(J$13-$I15))/(1+J$13)^$F$16)-$B$23)/$B$25,NA()) -> 48.857962 | K15: =IF(K$13>$I15,((SUMPRODUCT($B$14:$F$14,1/(1+K$13)^$B$16:$F$16)+($B$34*(1+$I15)/(K$13-$I15))/(1+K$13)^$F$16)-$B$23)/$B$25,NA()) -> 43.555041 | L15: =IF(L$13>$I15,((SUMPRODUCT($B$14:$F$14,1/(1+L$13)^$B$16:$F$16)+($B$34*(1+$I15)/(L$13-$I15))/(1+L$13)^$F$16)-$B$23)/$B$25,NA()) -> 39.16317 | M15: =IF(M$13>$I15,((SUMPRODUCT($B$14:$F$14,1/(1+M$13)^$B$16:$F$16)+($B$34*(1+$I15)/(M$13-$I15))/(1+M$13)^$F$16)-$B$23)/$B$25,NA()) -> 35.469966 | N15: =IF(N$13>$I15,((SUMPRODUCT($B$14:$F$14,1/(1+N$13)^$B$16:$F$16)+($B$34*(1+$I15)/(N$13-$I15))/(1+N$13)^$F$16)-$B$23)/$B$25,NA()) -> 32.324162
A16: Okres dyskontowania | B16: =1 -> 1 | C16: =2 -> 2 | D16: =3 -> 3 | E16: =4 -> 4 | F16: =5 -> 5 | I16: =$B$6 -> 0.03 | J16: =IF(J$13>$I16,((SUMPRODUCT($B$14:$F$14,1/(1+J$13)^$B$16:$F$16)+($B$34*(1+$I16)/(J$13-$I16))/(1+J$13)^$F$16)-$B$23)/$B$25,NA()) -> 54.373237 | K16: =IF(K$13>$I16,((SUMPRODUCT($B$14:$F$14,1/(1+K$13)^$B$16:$F$16)+($B$34*(1+$I16)/(K$13-$I16))/(1+K$13)^$F$16)-$B$23)/$B$25,NA()) -> 47.975829 | L16: =IF(L$13>$I16,((SUMPRODUCT($B$14:$F$14,1/(1+L$13)^$B$16:$F$16)+($B$34*(1+$I16)/(L$13-$I16))/(1+L$13)^$F$16)-$B$23)/$B$25,NA()) -> 42.773844 | M16: =IF(M$13>$I16,((SUMPRODUCT($B$14:$F$14,1/(1+M$13)^$B$16:$F$16)+($B$34*(1+$I16)/(M$13-$I16))/(1+M$13)^$F$16)-$B$23)/$B$25,NA()) -> 38.465385 | N16: =IF(N$13>$I16,((SUMPRODUCT($B$14:$F$14,1/(1+N$13)^$B$16:$F$16)+($B$34*(1+$I16)/(N$13-$I16))/(1+N$13)^$F$16)-$B$23)/$B$25,NA()) -> 34.842162
A17: Współczynnik dyskontowy | B17: =1/(1+$B$5)^B16 -> 0.92206788 | C17: =1/(1+$B$5)^C16 -> 0.85020918 | D17: =1/(1+$B$5)^D16 -> 0.78395058 | E17: =1/(1+$B$5)^E16 -> 0.72285565 | F17: =1/(1+$B$5)^F16 -> 0.66652198 | I17: =$B$6+0.5% -> 0.035 | J17: =IF(J$13>$I17,((SUMPRODUCT($B$14:$F$14,1/(1+J$13)^$B$16:$F$16)+($B$34*(1+$I17)/(J$13-$I17))/(1+J$13)^$F$16)-$B$23)/$B$25,NA()) -> 61.284119 | K17: =IF(K$13>$I17,((SUMPRODUCT($B$14:$F$14,1/(1+K$13)^$B$16:$F$16)+($B$34*(1+$I17)/(K$13-$I17))/(1+K$13)^$F$16)-$B$23)/$B$25,NA()) -> 53.389631 | L17: =IF(L$13>$I17,((SUMPRODUCT($B$14:$F$14,1/(1+L$13)^$B$16:$F$16)+($B$34*(1+$I17)/(L$13-$I17))/(1+L$13)^$F$16)-$B$23)/$B$25,NA()) -> 47.113668 | M17: =IF(M$13>$I17,((SUMPRODUCT($B$14:$F$14,1/(1+M$13)^$B$16:$F$16)+($B$34*(1+$I17)/(M$13-$I17))/(1+M$13)^$F$16)-$B$23)/$B$25,NA()) -> 42.010233 | N17: =IF(N$13>$I17,((SUMPRODUCT($B$14:$F$14,1/(1+N$13)^$B$16:$F$16)+($B$34*(1+$I17)/(N$13-$I17))/(1+N$13)^$F$16)-$B$23)/$B$25,NA()) -> 37.783221
A18: Wartość bieżąca nielewarowanych FCF | B18: =B14*B17 -> 125963.22 | C18: =C14*C17 -> 218314.17 | D18: =D14*D17 -> 339070.11 | E18: =E14*E17 -> 468308.21 | F18: =F14*F17 -> 564425.76 | I18: =$B$6+1% -> 0.04 | J18: =IF(J$13>$I18,((SUMPRODUCT($B$14:$F$14,1/(1+J$13)^$B$16:$F$16)+($B$34*(1+$I18)/(J$13-$I18))/(1+J$13)^$F$16)-$B$23)/$B$25,NA()) -> 70.19706 | K18: =IF(K$13>$I18,((SUMPRODUCT($B$14:$F$14,1/(1+K$13)^$B$16:$F$16)+($B$34*(1+$I18)/(K$13-$I18))/(1+K$13)^$F$16)-$B$23)/$B$25,NA()) -> 60.173363 | L18: =IF(L$13>$I18,((SUMPRODUCT($B$14:$F$14,1/(1+L$13)^$B$16:$F$16)+($B$34*(1+$I18)/(L$13-$I18))/(1+L$13)^$F$16)-$B$23)/$B$25,NA()) -> 52.428321 | M18: =IF(M$13>$I18,((SUMPRODUCT($B$14:$F$14,1/(1+M$13)^$B$16:$F$16)+($B$34*(1+$I18)/(M$13-$I18))/(1+M$13)^$F$16)-$B$23)/$B$25,NA()) -> 46.27094 | N18: =IF(N$13>$I18,((SUMPRODUCT($B$14:$F$14,1/(1+N$13)^$B$16:$F$16)+($B$34*(1+$I18)/(N$13-$I18))/(1+N$13)^$F$16)-$B$23)/$B$25,NA()) -> 41.263737
A19: Wartość rezydualna | G19: =F14*(1+$B$6)/($B$5-$B$6) -> 15998634
A20: Wartość bieżąca wartości rezydualnej | G20: =G19*F17 -> 10663441
A21: Podsumowanie wyceny — Scenariusz 1: dalszy wzrost nakładów inwestycyjnych
A22: Wartość przedsiębiorstwa | B22: =SUM(B18:F18)+G20 -> 12379522
A23: Mniej: dług netto / (gotówka netto) | B23: ='Model 3 sprawozdań'!G89 -> -199482
A24: Wartość kapitału własnego | B24: =B22-B23 -> 12579004
A25: Liczba akcji (tys.) | B25: =Założenia!B10 -> 980400
A26: Implikowana wartość / akcję (PLN) | B26: =B24/B25 -> 12.830482
A27: Bieżąca cena akcji (PLN) | B27: =Założenia!B9 -> 41
A28: Premia / (dyskonto) | B28: =B26/B27-1 -> -0.68706142
A29: Podsumowanie wyceny — Scenariusz 2: nakłady inwestycyjne w roku rezydualnym = amortyzacja
A30: NOPAT w roku rezydualnym | B30: =F10 -> 2746749.5
A31: Amortyzacja w roku rezydualnym | B31: =F11 -> 1302787.3
A32: Założenie nakładów inwestycyjnych w roku rezydualnym | B32: =-B31 -> -1302787.3
A33: Zmiana kapitału obrotowego netto w roku rezydualnym | B33: =F13 -> -431376.56
A34: UFCF w roku rezydualnym | B34: =SUM(B30:B32)-B33 -> 3178126.1
A35: Wartość rezydualna | B35: =B34*(1+$B$6)/($B$5-$B$6) -> 60042900
A36: Wartość bieżąca wartości rezydualnej | B36: =B35*F17 -> 40019913
A37: Wartość przedsiębiorstwa | B37: =SUM(B18:F18)+B36 -> 41735994
A38: Implikowana wartość / akcję (PLN) | B38: =(B37-B23)/B25 -> 42.773844
A39: Premia / (dyskonto) | B39: =B38/B27-1 -> 0.04326448

Sheet Kontrole
A1: Kontrole modelu
A2: Wszystkie kontrole powinny wynosić zero
A3: Miara | B3: 2020 | C3: 2021 | D3: 2022 | E3: 2023 | F3: 2024 | G3: 2025 | H3: 2026 | I3: 2027 | J3: 2028 | K3: 2029 | L3: 2030
A4: Kontrola bilansu | B4: ='Model 3 sprawozdań'!B86 -> 0 | C4: ='Model 3 sprawozdań'!C86 -> 0 | D4: ='Model 3 sprawozdań'!D86 -> 0 | E4: ='Model 3 sprawozdań'!E86 -> 0 | F4: ='Model 3 sprawozdań'!F86 -> 0 | G4: ='Model 3 sprawozdań'!G86 -> 0 | H4: ='Model 3 sprawozdań'!H86 -> 0 | I4: ='Model 3 sprawozdań'!I86 -> 0 | ... L4: ='Model 3 sprawozdań'!L86 -> 0
